<?xml version="1.0"?>
<robot xmlns:xacro="http://www.ros.org/wiki/xacro" name="pendulum">
    
    <!-- PLATFORM LINK -->
    <link name="base_link">
		<visual>
		    <origin xyz="0 0 0" rpy="0 0 0"/>
			<geometry>
				<cylinder length="0.03" radius="0.9"/>
			</geometry>
			<material name="Bordeux">
	       		<color rgba="0.35 0.09 0.07 1"/>
	     	</material>
		</visual>
        <collision>
		    <origin xyz="0 0 0" rpy="0 0 0"/>
			<geometry>
				<cylinder length="0.03" radius="1.5"/>
			</geometry>
        </collision>
        <inertial>
            <origin rpy="0 0 0" xyz="0 0 0" />
            <mass value="200" />
            <inertia ixx="112.5" ixy="0" ixz="0" iyy="112.5" iyz="0" izz="225" />
        </inertial>
	</link>
	<gazebo reference="base_link">
        <mu1>0.01</mu1>
        <mu2>0.01</mu2>
        <material>Gazebo/Tertiary</material>
        <self_collide>1</self_collide>
        <static>true</static>
    </gazebo>

    <!-- FIRST PLANAR JOINT -->
	<joint name="base_to_dull" type="prismatic">
    	<parent link="base_link"/>
	    <child link="dull_link_1"/>
    	<origin xyz="0 0 0.015"/>
   		<axis xyz="1 0 0"/>
        <limit lower="-0.5" upper="0.5" effort="100" velocity="10"/>
  	</joint>
    <transmission name="tran1">
        <type>transmission_interface/SimpleTransmission</type>
        <joint name="base_to_dull">
            <hardwareInterface>hardware_interface/EffortJointInterface</hardwareInterface>
        </joint>
        <actuator name="planar_motor_1">
            <hardwareInterface>hardware_interface/EffortJointInterface</hardwareInterface>
            <mechanicalReduction>1</mechanicalReduction>
        </actuator>
    </transmission>
	
    <!-- DULL LINK to make a planar joint -->
 	<link name="dull_link_1">
        <inertial>
            <origin rpy="0 0 0" xyz="0 0 0"/>
            <mass value="0.01" />
            <inertia ixx="1.4e-03" ixy="0.0" ixz="0.0" iyy="1.4e-03" iyz="0.0" izz="2.8e-03"/>
        </inertial>
        <visual>
            <origin rpy="0.0 0 0" xyz="0 0 0"/>
            <geometry>
				<cylinder length="0.02" radius="0.75"/>
			</geometry>
        </visual>
        <collision>
            <origin rpy="0.0 0 0" xyz="0 0 0"/>
            <geometry>
				<cylinder length="0.02" radius="0.75"/>
			</geometry>
        </collision>
	</link>
	<gazebo reference="dull_link_1">
        <mu1>0.01</mu1>
        <mu2>0.01</mu2>
        <material>Gazebo/Residential</material>
        <self_collide>1</self_collide>
    </gazebo>

    <!-- SECOND PLANAR JOINT -->
	<joint name="dull_to_platform" type="prismatic">
    	<parent link="dull_link_1"/>
	    <child link="platform"/>
    	<origin xyz="0 0 0.05"/>
   		<axis xyz="0 1 0"/>
        <limit lower="-0.5" upper="0.5" effort="100" velocity="10"/>
  	</joint>
    <transmission name="tran2">
        <type>transmission_interface/SimpleTransmission</type>
        <joint name="dull_to_platform">
            <hardwareInterface>hardware_interface/EffortJointInterface</hardwareInterface>
        </joint>
        <actuator name="planar_motor_2">
            <hardwareInterface>hardware_interface/EffortJointInterface</hardwareInterface>
            <mechanicalReduction>1</mechanicalReduction>
        </actuator>
    </transmission>

    <!-- Moving PLATFORM link -->
 	<link name="platform">
        <inertial>
            <origin rpy="0.0 0 0" xyz="0 0 0"/>
            <mass value="1.0" />
            <inertia ixx="3.3e-3" ixy="0.0" ixz="0.0" iyy="3.3e-3" iyz="0.0" izz="0.005"/>
        </inertial>
        <visual>
            <origin rpy="0.0 0 0" xyz="0 0 0"/>
            <geometry>
				<cylinder length="0.1" radius="0.1"/>
			</geometry>
        </visual>
        <collision>
            <origin rpy="0.0 0 0" xyz="0 0 0"/>
            <geometry>
				<cylinder length="0.1" radius="0.1"/>
			</geometry>
        </collision>
	</link>
	<gazebo reference="platform">
        <mu1>0.01</mu1>
        <mu2>0.01</mu2>
        <material>Gazebo/CoM</material>
        <self_collide>0</self_collide>
    </gazebo>

    <!-- FIXED Joint to BALL -->
	<joint name="fix_to_ball" type="fixed">
    	<parent link="platform"/>
	    <child link="ball"/>
    	<origin xyz="0 0 0.06"/>
  	</joint>

    <!-- BALL Link -->
 	<link name="ball">
        <inertial>
            <origin rpy="0.0 0 0" xyz="0 0 0"/>
            <mass value="0.1" />
            <inertia ixx="3.6e-05" ixy="0.0" ixz="0.0" iyy="3.6e-05" iyz="0.0" izz="3.6e-05"/>
        </inertial>
        <!--visual>
            <origin rpy="0.0 0 0" xyz="0 0 0"/>
            <geometry>
				<sphere radius="0.03"/>
			</geometry>
        </visual-->
        <collision>
            <origin rpy="0.0 0 0" xyz="0 0 0"/>
            <geometry>
				<sphere radius="0.03"/>
			</geometry>
        </collision>
	</link>
	<gazebo reference="ball">
        <mu1>0.01</mu1>
        <mu2>0.01</mu2>
        <material>Gazebo/Blue</material>
        <self_collide>1</self_collide>
    </gazebo>

    <!-- First BALL Joint -->
	<joint name="ball1_joint" type="revolute">
    	<parent link="ball"/>
	    <child link="ball2"/>
    	<origin xyz="0 0 0"/>
   		<axis xyz="1 0 0"/>
        <limit lower="-1.7" upper="1.7" effort="100" velocity="10"/>
  	</joint>


    <!-- Second BALL Link -->
 	<link name="ball2">
        <inertial>
            <origin rpy="0.0 0 0" xyz="0 0 0"/>
            <mass value="0.1" />
            <inertia ixx="3.6e-05" ixy="0.0" ixz="0.0" iyy="3.6e-05" iyz="0.0" izz="3.6e-05"/>
        </inertial>
        <visual>
            <origin rpy="0.0 0 0" xyz="0 0 0"/>
            <geometry>
				<sphere radius="0.03"/>
			</geometry>
        </visual>
        <collision>
            <origin rpy="0.0 0 0" xyz="0 0 0"/>
            <geometry>
				<sphere radius="0.03"/>
			</geometry>
        </collision>
	</link>
	<gazebo reference="ball2">
        <mu1>0.01</mu1>
        <mu2>0.01</mu2>
        <material>Gazebo/Wood</material>
        <self_collide>1</self_collide>
    </gazebo>

    <!-- Second BALL Joint -->
	<joint name="ball2_joint" type="revolute">
    	<parent link="ball2"/>
	    <child link="bar"/>
    	<origin xyz="0 0 0"/>
   		<axis xyz="0 1 0"/>
        <limit lower="-1.7" upper="1.7" effort="100" velocity="10"/>
  	</joint>

    <!-- Bar Link -->
 	<link name="bar">
        <inertial>
            <origin rpy="0 0 0" xyz="0 0 0.38"/>
            <mass value="0.1" />
            <inertia ixx="0.0032" ixy="0.0" ixz="0.0" iyy="0.0032" iyz="0.0" izz="5e-06"/>
        </inertial>
        <visual>
            <origin rpy="0 0 0" xyz="0 0 0.38"/>
            <geometry>
				<cylinder length="0.7" radius="0.01"/>
			</geometry>
        </visual>
        <collision>
            <origin rpy="0 0 0" xyz="0 0 0.38"/>
            <geometry>
				<cylinder length="0.7" radius="0.01"/>
			</geometry>
        </collision>
	</link>
	<gazebo reference="bar">
        <mu1>0.01</mu1>
        <mu2>0.01</mu2>
        <material>Gazebo/Wood</material>
        <self_collide>1</self_collide>
    </gazebo>

    <!-- FIXED Joint to BALL3 -->
	<joint name="bar_to_ball3" type="fixed">
    	<parent link="bar"/>
	    <child link="ball3"/>
    	<origin xyz="0 0 0.73"/>
  	</joint>

    <!-- BALL3 Link -->
 	<link name="ball3">
        <inertial>
            <origin rpy="0.0 0 0" xyz="0 0 0"/>
            <mass value="2" />
            <inertia ixx="7.2e-04" ixy="0.0" ixz="0.0" iyy="7.2e-04" iyz="0.0" izz="7.2e-04"/>
        </inertial>
        <visual>
            <origin rpy="0.0 0 0" xyz="0 0 0"/>
            <geometry>
				<sphere radius="0.03"/>
			</geometry>
        </visual>
        <collision>
            <origin rpy="0.0 0 0" xyz="0 0 0"/>
            <geometry>
				<sphere radius="0.03"/>
			</geometry>
        </collision>
	</link>
	<gazebo reference="ball3">
        <mu1>0.01</mu1>
        <mu2>0.01</mu2>
        <material>Gazebo/Wood</material>
        <self_collide>1</self_collide>
    </gazebo>

<!-- ROS Control Gazebo Plugin -->
<gazebo>
  <plugin name="gazebo_ros_control" filename="libgazebo_ros_control.so">
    <robotNamespace>/pendulum</robotNamespace>
  </plugin>
</gazebo>

</robot>


