<?xml version="1.0"?>
<robot xmlns:xacro="http://www.ros.org/wiki/xacro" name="pendulum">
    
    <!-- PLATFORM LINK -->
    <link name="base_link">
		<visual>
		    <origin xyz="0 0 0" rpy="0 0 0"/>
			<geometry>
				<box size="2.0 0.7 0.01"/>
			</geometry>
			<material name="Bordeux">
	       		<color rgba="0.35 0.09 0.07 1"/>
	     	</material>
		</visual>
        <collision>
		    <origin xyz="0 0 0" rpy="0 0 0"/>
			<geometry>
				<box size="2.0 0.7 0.03"/>
			</geometry>
        </collision>
        <inertial>
            <origin rpy="0 0 0" xyz="0 0 0" />
            <mass value="200" />
            <inertia ixx="4" ixy="0" ixz="0" iyy="40" iyz="0" izz="40" />
        </inertial>
	</link>
	<gazebo reference="base_link">
        <mu1>0.01</mu1>
        <mu2>0.01</mu2>
        <material>Gazebo/Tertiary</material>
        <self_collide>1</self_collide>
        <static>true</static>
    </gazebo>


    <!-- x PRISMATIC Joint -->
	<joint name="base_to_plat" type="prismatic">
    	<parent link="base_link"/>
	    <child link="platform"/>
    	<origin xyz="0 0 0.035"/>
   		<axis xyz="1 0 0"/>
        <limit lower="-0.7" upper="0.7" effort="1000" velocity="100"/>
  	</joint>
    <transmission name="tran2">
        <type>transmission_interface/SimpleTransmission</type>
        <joint name="base_to_plat">
            <hardwareInterface>hardware_interface/EffortJointInterface</hardwareInterface>
        </joint>
        <actuator name="planar_motor_2">
            <hardwareInterface>hardware_interface/EffortJointInterface</hardwareInterface>
            <mechanicalReduction>1</mechanicalReduction>
        </actuator>
    </transmission>

    <!-- Moving PLATFORM link -->
 	<link name="platform">
        <inertial>
            <origin rpy="0.0 0 0" xyz="0 0 0"/>
            <mass value="1.0" />
            <inertia ixx="5.3e-04" ixy="0.0" ixz="0.0" iyy="1.2e-3" iyz="0.0" izz="1.7e-03"/>
        </inertial>
        <visual>
            <origin rpy="0.0 0 0" xyz="0 0 0"/>
            <geometry>
				<box size="0.12 0.08 0.07"/>
			</geometry>
        </visual>
        <collision>
            <origin rpy="0.0 0 0" xyz="0 0 0"/>
            <geometry>
				<box size="0.12 0.08 0.07"/>
			</geometry>
        </collision>
	</link>
	<gazebo reference="platform">
        <mu1>0.01</mu1>
        <mu2>0.01</mu2>
        <material>Gazebo/CoM</material>
        <self_collide>1</self_collide>
    </gazebo>

    <!-- FIXED Joint to BALL -->
	<joint name="fix_to_ball" type="fixed">
    	<parent link="platform"/>
	    <child link="ball"/>
    	<origin xyz="0 0 0.03"/>
  	</joint>

    <!-- BALL Link -->
 	<link name="ball">
        <inertial>
            <origin rpy="0.0 0 0" xyz="0 0 0"/>
            <mass value="0.1" />
            <inertia ixx="3.6e-05" ixy="0.0" ixz="0.0" iyy="3.6e-05" iyz="0.0" izz="3.6e-05"/>
        </inertial>
        <visual>
            <origin rpy="0.0 0 0" xyz="0 0 0"/>
            <geometry>
				<sphere radius="0.03"/>
			</geometry>
        </visual>
        <collision>
            <origin rpy="0.0 0 0" xyz="0 0 0"/>
            <geometry>
				<sphere radius="0.03"/>
			</geometry>
        </collision>
	</link>
	<gazebo reference="ball">
        <mu1>0.01</mu1>
        <mu2>0.01</mu2>
        <material>Gazebo/Wood</material>
        <self_collide>0</self_collide>
    </gazebo>

    <!-- REVOLUTE Joint -->
	<joint name="revolute_joint" type="revolute">
    	<parent link="ball"/>
	    <child link="bar"/>
    	<origin xyz="0 0 0"/>
   		<axis xyz="0 1 0"/>
        <limit lower="-1.7" upper="1.7" effort="100" velocity="100"/>
        <dynamics damping="0" friction="0"/>
  	</joint>
    <transmission name="tran3">
        <type>transmission_interface/SimpleTransmission</type>
        <joint name="revolute_joint">
            <hardwareInterface>hardware_interface/EffortJointInterface</hardwareInterface>
        </joint>
        <actuator name="rev_motor">
            <hardwareInterface>hardware_interface/EffortJointInterface</hardwareInterface>
            <mechanicalReduction>1</mechanicalReduction>
        </actuator>
    </transmission>

    <!-- BAR link -->
 	<link name="bar">
        <inertial>
            <origin rpy="0 0 0" xyz="0 0 0.38"/>
            <mass value="0.1" />
            <inertia ixx="0.0032" ixy="0.0" ixz="0.0" iyy="0.0032" iyz="0.0" izz="5e-06"/>
        </inertial>
        <visual>
            <origin rpy="0 0 0" xyz="0 0 0.38"/>
            <geometry>
				<cylinder length="0.7" radius="0.01"/>
			</geometry>
        </visual>
        <collision>
            <origin rpy="0 0 0" xyz="0 0 0.38"/>
            <geometry>
				<cylinder length="0.7" radius="0.01"/>
			</geometry>
        </collision>
	</link>
	<gazebo reference="bar">
        <mu1>0.01</mu1>
        <mu2>0.01</mu2>
        <material>Gazebo/Wood</material>
        <self_collide>1</self_collide>
    </gazebo>

    <!-- FIXED Joint to BALL2 -->
	<joint name="bar_to_ball2" type="fixed">
    	<parent link="bar"/>
	    <child link="ball2"/>
    	<origin xyz="0 0 0.73"/>
  	</joint>

    <!-- BALL2 Link -->
 	<link name="ball2">
        <inertial>
            <origin rpy="0.0 0 0" xyz="0 0 0"/>
            <mass value="1" />
            <inertia ixx="3.6e-04" ixy="0.0" ixz="0.0" iyy="3.6e-04" iyz="0.0" izz="3.6e-04"/>
        </inertial>
        <visual>
            <origin rpy="0.0 0 0" xyz="0 0 0"/>
            <geometry>
				<sphere radius="0.03"/>
			</geometry>
        </visual>
        <collision>
            <origin rpy="0.0 0 0" xyz="0 0 0"/>
            <geometry>
				<sphere radius="0.03"/>
			</geometry>
        </collision>
	</link>
	<gazebo reference="ball2">
        <mu1>0.01</mu1>
        <mu2>0.01</mu2>
        <material>Gazebo/Wood</material>
        <self_collide>1</self_collide>
    </gazebo>

<!-- ROS Control Gazebo Plugin -->
<plugin name="joint_state_publisher" filename="libgazebo_ros_joint_state_publisher.so">
   <jointName>revolute_joint</jointName>
   <updateRate>50.0</updateRate>
   <alwaysOn>true</alwaysOn>
</plugin>

<gazebo>
  <plugin name="gazebo_ros_control" filename="libgazebo_ros_control.so">
    <robotNamespace>/pendulum</robotNamespace>
  </plugin>
</gazebo>


</robot>


